<?xml version="1.0" ?>
<robot name="krytn">
  <!--Generated by CROSS, a ROS Workbench for FreeCAD (https://github.com/galou/freecad.cross)-->
  <link name="base_footprint">
    <visual>
      <!--visual_base_footprint-->
      <origin rpy="0.0 -0.0 0.0" xyz="0.0 0.0 0.0"/>
      <geometry>
        <mesh filename="package://krytn_tray/meshes/krytn_tray_ex_visual_base_footprint_.dae"/>
      </geometry>
    </visual>
    <collision>
      <!--collision_base_footprint-->
      <origin rpy="0.0 -0.0 0.0" xyz="0.0 0.0 0.0"/>
      <geometry>
        <mesh filename="package://krytn_tray/meshes/krytn_tray_ex_collision_base_footprint_.dae"/>
      </geometry>
    </collision>
    <inertial>
      <mass value="0.0"/>
      <origin rpy="0.0 -0.0 0.0" xyz="0.0 0.0 0.0"/>
      <inertia ixx="0.0" ixy="0.0" ixz="0.0" iyy="0.0" iyz="0.0" izz="0.0"/>
    </inertial>
  </link>
  <link name="base_link">
    <visual>
      <!--visual_base_link/base_link_visual.-->
      <origin rpy="0.0 -0.0 0.0" xyz="-0.11 0.0 -0.029"/>
      <geometry>
        <mesh filename="package://krytn_tray/meshes/krytn_tray_ex_magni_body.dae.dae"/>
      </geometry>
    </visual>
    <collision>
      <!--collision_base_link/base_link_collision.-->
      <origin rpy="0.0 -0.0 0.0" xyz="-0.11 0.0 0.051"/>
      <geometry>
        <box size="0.398 0.268 0.16"/>
      </geometry>
    </collision>
    <collision>
      <!--collision_base_link/base_link_collision001.-->
      <origin rpy="0.0 -0.0 0.0" xyz="-0.136 0.0 0.148"/>
      <geometry>
        <box size="0.375 0.268 0.034"/>
      </geometry>
    </collision>
    <collision>
      <!--collision_base_link/base_link_collision002.-->
      <origin rpy="0.0 -0.0 0.0" xyz="-0.279 0.169 0.006"/>
      <geometry>
        <box size="0.1 0.07 0.07"/>
      </geometry>
    </collision>
    <collision>
      <!--collision_base_link/base_link_collision003.-->
      <origin rpy="0.0 -0.0 0.0" xyz="-0.279 -0.169 0.006"/>
      <geometry>
        <box size="0.1 0.07 0.07"/>
      </geometry>
    </collision>
    <inertial>
      <mass value="10.0"/>
      <origin rpy="0.0 -0.0 0.0" xyz="-0.15 0.0 0.03"/>
      <inertia ixx="0.059450809553" ixy="0.0" ixz="0.0" iyy="0.150753273032" iyz="0.0" izz="0.17270409758500002"/>
    </inertial>
  </link>
  <link name="left_wheel">
    <visual>
      <!--visual_left_wheel/left_wheel_visual.-->
      <origin rpy="0.0 -1.5707963267948966 0.0" xyz="-1.57652e-17 0.0 -0.071"/>
      <geometry>
        <mesh filename="package://krytn_tray/meshes/krytn_tray_ex_front_wheel.dae.dae"/>
      </geometry>
    </visual>
    <collision>
      <!--collision_left_wheel/left_wheel_collision.-->
      <origin rpy="0.0 -0.0 0.0" xyz="7.32747e-18 0.0 0.033"/>
      <geometry>
        <cylinder length="0.01" radius="0.1"/>
      </geometry>
    </collision>
    <inertial>
      <mass value="1.34"/>
      <origin rpy="-0.0 1.5707963267948966 0.0" xyz="0.0 0.0 0.0"/>
      <inertia ixx="0.003629165215000001" ixy="0.0" ixz="0.0" iyy="0.003629165215000001" iyz="0.0" izz="0.006700000000000001"/>
    </inertial>
  </link>
  <link name="right_wheel">
    <visual>
      <!--visual_right_wheel/right_wheel_visual.-->
      <origin rpy="-0.0 1.5707963267948961 0.0" xyz="1.57652e-17 0.0 0.071"/>
      <geometry>
        <mesh filename="package://krytn_tray/meshes/krytn_tray_ex_front_wheel.dae.dae"/>
      </geometry>
    </visual>
    <collision>
      <!--collision_right_wheel/right_wheel_collision.-->
      <origin rpy="0.0 -0.0 0.0" xyz="-7.32747e-18 0.0 -0.033"/>
      <geometry>
        <cylinder length="0.01" radius="0.1"/>
      </geometry>
    </collision>
    <inertial>
      <mass value="1.34"/>
      <origin rpy="-0.0 1.5707963267948966 0.0" xyz="0.0 0.0 0.0"/>
      <inertia ixx="0.003629165215000001" ixy="0.0" ixz="0.0" iyy="0.003629165215000001" iyz="0.0" izz="0.006700000000000001"/>
    </inertial>
  </link>
  <link name="left_caster_wheel">
    <visual>
      <!--visual_left_caster_wheel/left_caster_wheel_visual.-->
      <origin rpy="0.0 -0.0 3.141592653589793" xyz="-0.25 0.169 0.0"/>
      <geometry>
        <mesh filename="package://krytn_tray/meshes/krytn_tray_ex_caster_wheel.dae.dae"/>
      </geometry>
    </visual>
    <collision>
      <!--collision_left_caster_wheel/left_caster_wheel_collision.-->
      <geometry>
        <sphere radius="0.04"/>
      </geometry>
    </collision>
    <inertial>
      <mass value="0.0"/>
      <origin rpy="0.0 -0.0 0.0" xyz="0.0 0.0 0.0"/>
      <inertia ixx="0.0" ixy="0.0" ixz="0.0" iyy="0.0" iyz="0.0" izz="0.0"/>
    </inertial>
  </link>
  <link name="right_caster_wheel">
    <visual>
      <!--visual_right_caster_wheel/right_caster_wheel_visual.-->
      <origin rpy="0.0 -0.0 3.141592653589793" xyz="-0.25 -0.169 0.0"/>
      <geometry>
        <mesh filename="package://krytn_tray/meshes/krytn_tray_ex_caster_wheel.dae.dae"/>
      </geometry>
    </visual>
    <collision>
      <!--collision_right_caster_wheel/right_caster_wheel_collision.-->
      <geometry>
        <sphere radius="0.04"/>
      </geometry>
    </collision>
    <inertial>
      <mass value="0.0"/>
      <origin rpy="0.0 -0.0 0.0" xyz="0.0 0.0 0.0"/>
      <inertia ixx="0.0" ixy="0.0" ixz="0.0" iyy="0.0" iyz="0.0" izz="0.0"/>
    </inertial>
  </link>
  <link name="realsense_link">
    <visual>
      <!--visual_realsense_link/realsense_link_visual.-->
      <origin rpy="0.0 -0.0 1.5707963267948966" xyz="0.0 0.0 0.0"/>
      <geometry>
        <mesh filename="package://krytn_tray/meshes/krytn_tray_ex_realsense.dae.dae"/>
      </geometry>
    </visual>
    <collision>
      <!--collision_realsense_link/realsense_link_collision.-->
      <origin rpy="0.0 -0.0 1.5707963267948966" xyz="0.0 0.0 0.0"/>
      <geometry>
        <mesh filename="package://krytn_tray/meshes/krytn_tray_ex_realsense.dae.dae"/>
      </geometry>
    </collision>
    <inertial>
      <mass value="0.06"/>
      <origin rpy="0.0 -0.0 0.0" xyz="-0.15 0.0 0.03"/>
      <inertia ixx="5.04999798e-05" ixy="0.0" ixz="0.0" iyy="2.499999e-06" iyz="0.0" izz="5.19999792e-05"/>
    </inertial>
  </link>
  <link name="lidar_2d_link">
    <visual>
      <!--visual_lidar_2d_link/lidar_2d_link_visual.-->
      <origin rpy="0.0 -0.0 0.0" xyz="0.0 0.0 0.0"/>
      <geometry>
        <mesh filename="package://krytn_tray/meshes/krytn_tray_ex_lidar_2d_v1.dae.dae"/>
      </geometry>
    </visual>
    <collision>
      <!--collision_lidar_2d_link/lidar_2d_link_collision.-->
      <origin rpy="0.0 -0.0 0.0" xyz="0.0 0.0 0.0"/>
      <geometry>
        <box size="0.05001062 0.05001062 0.035003035"/>
      </geometry>
    </collision>
    <collision>
      <!--collision_lidar_2d_link/lidar_2d_link_collision001.-->
      <origin rpy="0.0 -0.0 0.0" xyz="0.0 0.0 0.0"/>
      <geometry>
        <cylinder length="0.035003035" radius="0.02"/>
      </geometry>
    </collision>
    <inertial>
      <mass value="0.13"/>
      <origin rpy="0.0 -0.0 0.0" xyz="-0.15 0.0 0.03"/>
      <inertia ixx="0.0027180822461000003" ixy="0.0" ixz="0.0" iyy="3.6833318600000004e-05" iyz="0.0" izz="0.0027354155725000003"/>
    </inertial>
  </link>
  <link name="krytn_tray">
    <visual>
      <!--Krytn tray part/Body.-->
      <origin rpy="0.0 -0.0 0.0" xyz="0.0 0.0 0.0"/>
      <geometry>
        <mesh filename="package://krytn_tray/meshes/krytn_tray_ex_Krytn_Tray.dae"/>
      </geometry>
    </visual>
    <collision>
      <!--Krytn tray part/Body.-->
      <origin rpy="0.0 -0.0 0.0" xyz="0.0 0.0 0.0"/>
      <geometry>
        <mesh filename="package://krytn_tray/meshes/krytn_tray_ex_Krytn_Tray.dae"/>
      </geometry>
    </collision>
    <inertial>
      <mass value="0.0"/>
      <origin rpy="0.0 -0.0 0.0" xyz="0.0 0.0 0.0"/>
      <inertia ixx="0.0" ixy="0.0" ixz="0.0" iyy="0.0" iyz="0.0" izz="0.0"/>
    </inertial>
  </link>
  <joint name="base_footprint_joint" type="fixed">
    <parent link="base_footprint"/>
    <child link="base_link"/>
    <origin rpy="0.0 -0.0 0.0" xyz="0.0 0.0 0.1"/>
  </joint>
  <joint name="left_wheel_joint" type="continuous">
    <parent link="base_link"/>
    <child link="left_wheel"/>
    <origin rpy="-1.5707963267948966 1.5707963267948963 0.0" xyz="0.0 0.163 0.0"/>
    <axis xyz="0 0 1"/>
  </joint>
  <joint name="right_wheel_joint" type="continuous">
    <parent link="base_link"/>
    <child link="right_wheel"/>
    <origin rpy="-1.5707963267948966 1.5707963267948963 0.0" xyz="0.0 -0.163 0.0"/>
    <axis xyz="0 0 1"/>
  </joint>
  <joint name="left_caster_wheel_joint" type="fixed">
    <parent link="base_link"/>
    <child link="left_caster_wheel"/>
    <origin rpy="0.0 -0.0 0.0" xyz="0.0 0.0 0.0"/>
  </joint>
  <joint name="right_caster_wheel_joint" type="fixed">
    <parent link="base_link"/>
    <child link="right_caster_wheel"/>
    <origin rpy="0.0 -0.0 0.0" xyz="0.0 0.0 0.0"/>
  </joint>
  <joint name="realsense_joint" type="fixed">
    <parent link="base_link"/>
    <child link="realsense_link"/>
    <origin rpy="0.0 -0.0 0.0" xyz="0.0 0.0 0.3"/>
  </joint>
  <joint name="lidar_2d_joint" type="fixed">
    <parent link="base_link"/>
    <child link="lidar_2d_link"/>
    <origin rpy="0.0 -0.0 0.0" xyz="0.0 0.0 0.15"/>
  </joint>
  <joint name="tray_joint" type="fixed">
    <parent link="base_link"/>
    <child link="krytn_tray"/>
    <origin rpy="0.0 -0.0 1.5707963267948966" xyz="-0.3 0.01 0.168"/>
  </joint>
</robot>
