<?xml version="1.0" ?>
<robot name="Robot">
  <!--Generated by CROSS, a ROS Workbench for FreeCAD (https://github.com/galou/freecad.cross)-->
  <link name="base_link">
    <visual>
      <!--Box_Chassis/Body001.-->
      <origin rpy="0.0 -0.0 0.0" xyz="0.0 0.0 0.0"/>
      <geometry>
        <mesh filename="package://forklift_freecad/meshes/forkliftv2_Forklift_Chassis.dae"/>
      </geometry>
    </visual>
    <collision>
      <!--Box_Chassis/Body001.-->
      <origin rpy="0.0 -0.0 0.0" xyz="0.0 0.0 0.0"/>
      <geometry>
        <mesh filename="package://forklift_freecad/meshes/forkliftv2_Forklift_Chassis.dae"/>
      </geometry>
    </collision>
    <inertial>
      <mass value="100.0"/>
      <origin rpy="0.0 -0.0 0.0" xyz="-0.4 0 0"/>
      <inertia ixx="0.0006186158699452" ixy="-0.0" ixz="-0.0" iyy="0.0011245930581975" iyz="-0.0" izz="0.0006186158699452"/>
    </inertial>
  </link>
  <link name="left_wheel">
    <visual>
      <!--Adjustable Wheel/Body.-->
      <origin rpy="0.0 -0.0 0.0" xyz="0.0 0.0 0.0"/>
      <geometry>
        <mesh filename="package://forklift_freecad/meshes/forkliftv2_Body.dae"/>
      </geometry>
    </visual>
    <collision>
      <!--Adjustable Wheel.Body_bbox-->
      <origin rpy="0.0 -0.0 0.0" xyz="0.0 0.0 0.015"/>
      <geometry>
        <cylinder length="0.03000000000000005" radius="0.1"/>
      </geometry>
    </collision>
    <inertial>
      <mass value="0.7509245446194294"/>
      <origin rpy="0.0 -0.0 0.0" xyz="-1.38e-17 -2.1e-18 -1e-19"/>
      <inertia ixx="0.0006186158699452" ixy="-0.0" ixz="-0.0" iyy="0.0011245930581975" iyz="-0.0" izz="0.0006186158699452"/>
    </inertial>
  </link>
  <link name="right_wheel">
    <visual>
      <!--Adjustable Wheel/Body.-->
      <origin rpy="0.0 -0.0 0.0" xyz="0.0 0.0 0.0"/>
      <geometry>
        <mesh filename="package://forklift_freecad/meshes/forkliftv2_Body.dae"/>
      </geometry>
    </visual>
    <collision>
      <!--Adjustable Wheel.Body_bbox-->
      <origin rpy="0.0 -0.0 0.0" xyz="0.0 0.0 0.015"/>
      <geometry>
        <cylinder length="0.1000000000000005" radius="0.1"/>
      </geometry>
    </collision>
    <inertial>
      <mass value="0.7509245446194294"/>
      <origin rpy="0.0 -0.0 0.0" xyz="-1.38e-17 -2.1e-18 -1e-19"/>
      <inertia ixx="0.0006186158699452" ixy="-0.0" ixz="-0.0" iyy="0.0011245930581975" iyz="-0.0" izz="0.0006186158699452"/>
    </inertial>
  </link>
  <link name="tines_link">
    <visual>
      <!--Tines/Body002.-->
      <origin rpy="0.0 -0.0 0.0" xyz="0.0 0.0 0.0"/>
      <geometry>
        <mesh filename="package://forklift_freecad/meshes/forkliftv2_Body002.dae"/>
      </geometry>
    </visual>
    <collision>
      <!--Tines/Body002.-->
      <origin rpy="0.0 -0.0 0.0" xyz="0.0 0.0 0.0"/>
      <geometry>
        <mesh filename="package://forklift_freecad/meshes/forkliftv2_Body002.dae"/>
      </geometry>
    </collision>
    <inertial>
      <mass value="0.7509245446194294"/>
      <origin rpy="0.0 -0.0 0.0" xyz="-1.38e-17 -2.1e-18 -1e-19"/>
      <inertia ixx="0.0006186158699452" ixy="-0.0" ixz="-0.0" iyy="0.0011245930581975" iyz="-0.0" izz="0.0006186158699452"/>
    </inertial>

  </link>
  <link name="back_left_wheel">
    <visual>
      <!--Adjustable Wheel/Body.-->
      <origin rpy="0.0 -0.0 0.0" xyz="0.0 0.0 0.0"/>
      <geometry>
        <mesh filename="package://forklift_freecad/meshes/forkliftv2_Body.dae"/>
      </geometry>
    </visual>
    <collision>
      <!--Adjustable Wheel.Body_bbox-->
      <origin rpy="0.0 -0.0 0.0" xyz="0.0 0.0 0.015"/>
      <geometry>
        <cylinder length="0.1000000000000005" radius="0.1"/>
      </geometry>
    </collision>
    <inertial>
      <mass value="0.7509245446194294"/>
      <origin rpy="0.0 -0.0 0.0" xyz="-1.38e-17 -2.1e-18 -1e-19"/>
      <inertia ixx="0.0006186158699452" ixy="-0.0" ixz="-0.0" iyy="0.0011245930581975" iyz="-0.0" izz="0.0006186158699452"/>
    </inertial>
  </link>
  <link name="back_right_wheel">
    <visual>
      <!--Adjustable Wheel/Body.-->
      <origin rpy="0.0 -0.0 0.0" xyz="0.0 0.0 0.0"/>
      <geometry>
        <mesh filename="package://forklift_freecad/meshes/forkliftv2_Body.dae"/>
      </geometry>
    </visual>
    <collision>
      <!--Adjustable Wheel.Body_bbox-->
      <origin rpy="0.0 -0.0 0.0" xyz="0.0 0.0 0.015"/>
      <geometry>
        <cylinder length="0.1000000000000005" radius="0.1"/>
      </geometry>
    </collision>
    <inertial>
      <mass value="0.7509245446194294"/>
      <origin rpy="0.0 -0.0 0.0" xyz="-1.38e-17 -2.1e-18 -1e-19"/>
      <inertia ixx="0.0006186158699452" ixy="-0.0" ixz="-0.0" iyy="0.0011245930581975" iyz="-0.0" izz="0.0006186158699452"/>
    </inertial>
  </link>
  <joint name="left_wheel_joint" type="continuous">
    <parent link="base_link"/>
    <child link="left_wheel"/>
    <origin rpy="-1.5707963267948966 0.0 0.0" xyz="-0.8 -0.3 0.0"/>
    <axis xyz="0 0 -1"/>
  </joint>
  <joint name="right_wheel_joint" type="continuous">
    <parent link="base_link"/>
    <child link="right_wheel"/>
    <origin rpy="-1.5707963267948966 0.0 0.0" xyz="-0.8 0.3 0.0"/>
    <axis xyz="0 0 -1"/>
  </joint>
  <joint name="tines_joint" type="prismatic">
    <parent link="base_link"/>
    <child link="tines_link"/>
    <origin rpy="0.0 -0.0 0.0" xyz="-0.0 0.0 0.0"/>
    <axis xyz="0 0 1"/>
    <limit effort="10000.0" lower="-0.1" upper="1.0" velocity="10.0"/>
  </joint>
  <joint name="back_left_joint" type="continuous">
    <parent link="base_link"/>
    <child link="back_left_wheel"/>
    <origin rpy="-1.5707963267948966 0.0 0.0" xyz="-0.3 -0.3 0.0"/>
    <axis xyz="0 0 -1"/>
  </joint>
  <joint name="back_right_joint" type="continuous">
    <parent link="base_link"/>
    <child link="back_right_wheel"/>
    <origin rpy="-1.5707963267948966 0.0 0.0" xyz="-0.3 0.3 0.0"/>
    <axis xyz="0 0 -1"/>
  </joint>
</robot>
